Workbook

Sheet Summary
A1: AI Software Engineer - 2026 sprint plan
A2: 28 Sep 2026 -> 31 Dec 2026. Tick tasks in 'Daily Plan' column L (choose ☑). Every number on this page is a formula over the other sheets.
A3: How to use: only edit the blue/yellow cells - Done (☐/☑) in Daily Plan / Projects / Papers, Status in Projects, and Notes. Excel 365 users may convert the Done column to native checkboxes (Insert > Checkbox); the formulas count both.
A5: Overall progress
A6: Start date | B6: =MIN('Daily Plan'!$B$2:$B$168) -> 46293
A7: End date | B7: =MAX('Daily Plan'!$B$2:$B$168) -> 46387
A8: Study days | B8: =SUMPRODUCT(1/COUNTIF('Daily Plan'!$B$2:$B$168,'Daily Plan'!$B$2:$B$168)) -> 82
A9: Tasks planned | B9: =COUNTA('Daily Plan'!$G$2:$G$168) -> 167
A10: Tasks done | B10: =(COUNTIF('Daily Plan'!$L$2:$L$168,"☑")+COUNTIF('Daily Plan'!$L$2:$L$168,TRUE())) -> 0
A11: Tasks done (%) | B11: =IFERROR(B10/B9,0) -> 0
A12: Hours planned | B12: =SUM('Daily Plan'!$J$2:$J$168) -> 290
A13: Hours done | B13: =SUMIF('Daily Plan'!$L$2:$L$168,"☑",'Daily Plan'!$J$2:$J$168)+SUMIF('Daily Plan'!$L$2:$L$168,TRUE(),'Daily Plan'!$J$2:$J$168) -> 0
A14: Hours done (%) | B14: =IFERROR(B13/B12,0) -> 0
A15: Tasks scheduled up to today | B15: =COUNTIF('Daily Plan'!$B$2:$B$168,"<="&TODAY()) -> 3
A16: Ahead (+) / behind (-) in tasks | B16: =B10-B15 -> -3
A17: Projects done | B17: =(COUNTIF(Projects!$H$2:$H$13,"☑")+COUNTIF(Projects!$H$2:$H$13,TRUE())) -> 0
A18: Papers read | B18: =(COUNTIF(Papers!$N$2:$N$82,"☑")+COUNTIF(Papers!$N$2:$N$82,TRUE())) -> 0
A19: Assumptions: 3.5 h Mon-Fri, 4.0 h Sat, Sunday rest; 25 Dec is a 0-hour buffer. Source: plan design (tools/plan_data.py).
A21: Progress by phase
A22: Phase | B22: Code | C22: Tasks | D22: Done | E22: Done % | F22: Hours | G22: Hours done
A23: Phase 0 - ML/DL revision | B23: P0 | C23: =COUNTIF('Daily Plan'!$E$2:$E$168,B23) -> 8 | D23: =COUNTIFS('Daily Plan'!$E$2:$E$168,B23,'Daily Plan'!$L$2:$L$168,"☑")+COUNTIFS('Daily Plan'!$E$2:$E$168,B23,'Daily Plan'!$L$2:$L$168,TRUE()) -> 0 | E23: =IFERROR(D23/C23,0) -> 0 | F23: =SUMIF('Daily Plan'!$E$2:$E$168,B23,'Daily Plan'!$J$2:$J$168) -> 10.5 | G23: =SUMIFS('Daily Plan'!$J$2:$J$168,'Daily Plan'!$E$2:$E$168,B23,'Daily Plan'!$L$2:$L$168,"☑")+SUMIFS('Daily Plan'!$J$2:$J$168,'Daily Plan'!$E$2:$E$168,B23,'Daily Plan'!$L$2:$L$168,TRUE()) -> 0
A24: Phase 1 - Transformers | B24: P1 | C24: =COUNTIF('Daily Plan'!$E$2:$E$168,B24) -> 19 | D24: =COUNTIFS('Daily Plan'!$E$2:$E$168,B24,'Daily Plan'!$L$2:$L$168,"☑")+COUNTIFS('Daily Plan'!$E$2:$E$168,B24,'Daily Plan'!$L$2:$L$168,TRUE()) -> 0 | E24: =IFERROR(D24/C24,0) -> 0 | F24: =SUMIF('Daily Plan'!$E$2:$E$168,B24,'Daily Plan'!$J$2:$J$168) -> 34 | G24: =SUMIFS('Daily Plan'!$J$2:$J$168,'Daily Plan'!$E$2:$E$168,B24,'Daily Plan'!$L$2:$L$168,"☑")+SUMIFS('Daily Plan'!$J$2:$J$168,'Daily Plan'!$E$2:$E$168,B24,'Daily Plan'!$L$2:$L$168,TRUE()) -> 0
A25: Phase 2 - LLMs & language modeling | B25: P2 | C25: =COUNTIF('Daily Plan'!$E$2:$E$168,B25) -> 16 | D25: =COUNTIFS('Daily Plan'!$E$2:$E$168,B25,'Daily Plan'!$L$2:$L$168,"☑")+COUNTIFS('Daily Plan'!$E$2:$E$168,B25,'Daily Plan'!$L$2:$L$168,TRUE()) -> 0 | E25: =IFERROR(D25/C25,0) -> 0 | F25: =SUMIF('Daily Plan'!$E$2:$E$168,B25,'Daily Plan'!$J$2:$J$168) -> 30 | G25: =SUMIFS('Daily Plan'!$J$2:$J$168,'Daily Plan'!$E$2:$E$168,B25,'Daily Plan'!$L$2:$L$168,"☑")+SUMIFS('Daily Plan'!$J$2:$J$168,'Daily Plan'!$E$2:$E$168,B25,'Daily Plan'!$L$2:$L$168,TRUE()) -> 0
A26: Phase 3 - Embeddings & information retrieval | B26: P3 | C26: =COUNTIF('Daily Plan'!$E$2:$E$168,B26) -> 11 | D26: =COUNTIFS('Daily Plan'!$E$2:$E$168,B26,'Daily Plan'!$L$2:$L$168,"☑")+COUNTIFS('Daily Plan'!$E$2:$E$168,B26,'Daily Plan'!$L$2:$L$168,TRUE()) -> 0 | E26: =IFERROR(D26/C26,0) -> 0 | F26: =SUMIF('Daily Plan'!$E$2:$E$168,B26,'Daily Plan'!$J$2:$J$168) -> 19 | G26: =SUMIFS('Daily Plan'!$J$2:$J$168,'Daily Plan'!$E$2:$E$168,B26,'Daily Plan'!$L$2:$L$168,"☑")+SUMIFS('Daily Plan'!$J$2:$J$168,'Daily Plan'!$E$2:$E$168,B26,'Daily Plan'!$L$2:$L$168,TRUE()) -> 0
A27: Phase 4 - RAG | B27: P4 | C27: =COUNTIF('Daily Plan'!$E$2:$E$168,B27) -> 13 | D27: =COUNTIFS('Daily Plan'!$E$2:$E$168,B27,'Daily Plan'!$L$2:$L$168,"☑")+COUNTIFS('Daily Plan'!$E$2:$E$168,B27,'Daily Plan'!$L$2:$L$168,TRUE()) -> 0 | E27: =IFERROR(D27/C27,0) -> 0 | F27: =SUMIF('Daily Plan'!$E$2:$E$168,B27,'Daily Plan'!$J$2:$J$168) -> 20.5 | G27: =SUMIFS('Daily Plan'!$J$2:$J$168,'Daily Plan'!$E$2:$E$168,B27,'Daily Plan'!$L$2:$L$168,"☑")+SUMIFS('Daily Plan'!$J$2:$J$168,'Daily Plan'!$E$2:$E$168,B27,'Daily Plan'!$L$2:$L$168,TRUE()) -> 0
A28: Phase 5 - LLM evaluation | B28: P5 | C28: =COUNTIF('Daily Plan'!$E$2:$E$168,B28) -> 12 | D28: =COUNTIFS('Daily Plan'!$E$2:$E$168,B28,'Daily Plan'!$L$2:$L$168,"☑")+COUNTIFS('Daily Plan'!$E$2:$E$168,B28,'Daily Plan'!$L$2:$L$168,TRUE()) -> 0 | E28: =IFERROR(D28/C28,0) -> 0 | F28: =SUMIF('Daily Plan'!$E$2:$E$168,B28,'Daily Plan'!$J$2:$J$168) -> 20 | G28: =SUMIFS('Daily Plan'!$J$2:$J$168,'Daily Plan'!$E$2:$E$168,B28,'Daily Plan'!$L$2:$L$168,"☑")+SUMIFS('Daily Plan'!$J$2:$J$168,'Daily Plan'!$E$2:$E$168,B28,'Daily Plan'!$L$2:$L$168,TRUE()) -> 0
A29: Phase 6 - Fine-tuning & post-training | B29: P6 | C29: =COUNTIF('Daily Plan'!$E$2:$E$168,B29) -> 12 | D29: =COUNTIFS('Daily Plan'!$E$2:$E$168,B29,'Daily Plan'!$L$2:$L$168,"☑")+COUNTIFS('Daily Plan'!$E$2:$E$168,B29,'Daily Plan'!$L$2:$L$168,TRUE()) -> 0 | E29: =IFERROR(D29/C29,0) -> 0 | F29: =SUMIF('Daily Plan'!$E$2:$E$168,B29,'Daily Plan'!$J$2:$J$168) -> 22 | G29: =SUMIFS('Daily Plan'!$J$2:$J$168,'Daily Plan'!$E$2:$E$168,B29,'Daily Plan'!$L$2:$L$168,"☑")+SUMIFS('Daily Plan'!$J$2:$J$168,'Daily Plan'!$E$2:$E$168,B29,'Daily Plan'!$L$2:$L$168,TRUE()) -> 0
A30: Phase 7 - AI agents | B30: P7 | C30: =COUNTIF('Daily Plan'!$E$2:$E$168,B30) -> 11 | D30: =COUNTIFS('Daily Plan'!$E$2:$E$168,B30,'Daily Plan'!$L$2:$L$168,"☑")+COUNTIFS('Daily Plan'!$E$2:$E$168,B30,'Daily Plan'!$L$2:$L$168,TRUE()) -> 0 | E30: =IFERROR(D30/C30,0) -> 0 | F30: =SUMIF('Daily Plan'!$E$2:$E$168,B30,'Daily Plan'!$J$2:$J$168) -> 18 | G30: =SUMIFS('Daily Plan'!$J$2:$J$168,'Daily Plan'!$E$2:$E$168,B30,'Daily Plan'!$L$2:$L$168,"☑")+SUMIFS('Daily Plan'!$J$2:$J$168,'Daily Plan'!$E$2:$E$168,B30,'Daily Plan'!$L$2:$L$168,TRUE()) -> 0
A31: Phase 8 - MCP | B31: P8 | C31: =COUNTIF('Daily Plan'!$E$2:$E$168,B31) -> 2 | D31: =COUNTIFS('Daily Plan'!$E$2:$E$168,B31,'Daily Plan'!$L$2:$L$168,"☑")+COUNTIFS('Daily Plan'!$E$2:$E$168,B31,'Daily Plan'!$L$2:$L$168,TRUE()) -> 0 | E31: =IFERROR(D31/C31,0) -> 0 | F31: =SUMIF('Daily Plan'!$E$2:$E$168,B31,'Daily Plan'!$J$2:$J$168) -> 3.5 | G31: =SUMIFS('Daily Plan'!$J$2:$J$168,'Daily Plan'!$E$2:$E$168,B31,'Daily Plan'!$L$2:$L$168,"☑")+SUMIFS('Daily Plan'!$J$2:$J$168,'Daily Plan'!$E$2:$E$168,B31,'Daily Plan'!$L$2:$L$168,TRUE()) -> 0
A32: Phase 9 - Inference & GPU optimization | B32: P9 | C32: =COUNTIF('Daily Plan'!$E$2:$E$168,B32) -> 12 | D32: =COUNTIFS('Daily Plan'!$E$2:$E$168,B32,'Daily Plan'!$L$2:$L$168,"☑")+COUNTIFS('Daily Plan'!$E$2:$E$168,B32,'Daily Plan'!$L$2:$L$168,TRUE()) -> 0 | E32: =IFERROR(D32/C32,0) -> 0 | F32: =SUMIF('Daily Plan'!$E$2:$E$168,B32,'Daily Plan'!$J$2:$J$168) -> 19 | G32: =SUMIFS('Daily Plan'!$J$2:$J$168,'Daily Plan'!$E$2:$E$168,B32,'Daily Plan'!$L$2:$L$168,"☑")+SUMIFS('Daily Plan'!$J$2:$J$168,'Daily Plan'!$E$2:$E$168,B32,'Daily Plan'!$L$2:$L$168,TRUE()) -> 0
A33: Phase 10 - Multimodal AI | B33: P10 | C33: =COUNTIF('Daily Plan'!$E$2:$E$168,B33) -> 8 | D33: =COUNTIFS('Daily Plan'!$E$2:$E$168,B33,'Daily Plan'!$L$2:$L$168,"☑")+COUNTIFS('Daily Plan'!$E$2:$E$168,B33,'Daily Plan'!$L$2:$L$168,TRUE()) -> 0 | E33: =IFERROR(D33/C33,0) -> 0 | F33: =SUMIF('Daily Plan'!$E$2:$E$168,B33,'Daily Plan'!$J$2:$J$168) -> 14.5 | G33: =SUMIFS('Daily Plan'!$J$2:$J$168,'Daily Plan'!$E$2:$E$168,B33,'Daily Plan'!$L$2:$L$168,"☑")+SUMIFS('Daily Plan'!$J$2:$J$168,'Daily Plan'!$E$2:$E$168,B33,'Daily Plan'!$L$2:$L$168,TRUE()) -> 0
A34: Phase 11 - Advanced LLM training (distributed, data, scaling) | B34: P11 | C34: =COUNTIF('Daily Plan'!$E$2:$E$168,B34) -> 5 | D34: =COUNTIFS('Daily Plan'!$E$2:$E$168,B34,'Daily Plan'!$L$2:$L$168,"☑")+COUNTIFS('Daily Plan'!$E$2:$E$168,B34,'Daily Plan'!$L$2:$L$168,TRUE()) -> 0 | E34: =IFERROR(D34/C34,0) -> 0 | F34: =SUMIF('Daily Plan'!$E$2:$E$168,B34,'Daily Plan'!$J$2:$J$168) -> 8.5 | G34: =SUMIFS('Daily Plan'!$J$2:$J$168,'Daily Plan'!$E$2:$E$168,B34,'Daily Plan'!$L$2:$L$168,"☑")+SUMIFS('Daily Plan'!$J$2:$J$168,'Daily Plan'!$E$2:$E$168,B34,'Daily Plan'!$L$2:$L$168,TRUE()) -> 0
... A37: Capstone - AI Software Engineer | B37: CAP | C37: =COUNTIF('Daily Plan'!$E$2:$E$168,B37) -> 10 | D37: =COUNTIFS('Daily Plan'!$E$2:$E$168,B37,'Daily Plan'!$L$2:$L$168,"☑")+COUNTIFS('Daily Plan'!$E$2:$E$168,B37,'Daily Plan'!$L$2:$L$168,TRUE()) -> 0 | E37: =IFERROR(D37/C37,0) -> 0 | F37: =SUMIF('Daily Plan'!$E$2:$E$168,B37,'Daily Plan'!$J$2:$J$168) -> 27 | G37: =SUMIFS('Daily Plan'!$J$2:$J$168,'Daily Plan'!$E$2:$E$168,B37,'Daily Plan'!$L$2:$L$168,"☑")+SUMIFS('Daily Plan'!$J$2:$J$168,'Daily Plan'!$E$2:$E$168,B37,'Daily Plan'!$L$2:$L$168,TRUE()) -> 0
A39: Progress by week
A40: Week focus | B40: Week | C40: Starts | D40: Tasks | E40: Done | F40: Done % | G40: Hours
A41: Diagnostic revision -> attention from scratch | B41: W1 | C41: 46293 | D41: =COUNTIF('Daily Plan'!$D$2:$D$168,B41) -> 15 | E41: =COUNTIFS('Daily Plan'!$D$2:$D$168,B41,'Daily Plan'!$L$2:$L$168,"☑")+COUNTIFS('Daily Plan'!$D$2:$D$168,B41,'Daily Plan'!$L$2:$L$168,TRUE()) -> 0 | F41: =IFERROR(E41/D41,0) -> 0 | G41: =SUMIF('Daily Plan'!$D$2:$D$168,B41,'Daily Plan'!$J$2:$J$168) -> 21.5
A42: The modern Transformer block (Llama-style) + encoder-decoder | B42: W2 | C42: 46300 | D42: =COUNTIF('Daily Plan'!$D$2:$D$168,B42) -> 13 | E42: =COUNTIFS('Daily Plan'!$D$2:$D$168,B42,'Daily Plan'!$L$2:$L$168,"☑")+COUNTIFS('Daily Plan'!$D$2:$D$168,B42,'Daily Plan'!$L$2:$L$168,TRUE()) -> 0 | F42: =IFERROR(E42/D42,0) -> 0 | G42: =SUMIF('Daily Plan'!$D$2:$D$168,B42,'Daily Plan'!$J$2:$J$168) -> 21.5
A43: Tokenization + training a small GPT (CS336 Assignment 1) | B43: W3 | C43: 46307 | D43: =COUNTIF('Daily Plan'!$D$2:$D$168,B43) -> 11 | E43: =COUNTIFS('Daily Plan'!$D$2:$D$168,B43,'Daily Plan'!$L$2:$L$168,"☑")+COUNTIFS('Daily Plan'!$D$2:$D$168,B43,'Daily Plan'!$L$2:$L$168,TRUE()) -> 0 | F43: =IFERROR(E43/D43,0) -> 0 | G43: =SUMIF('Daily Plan'!$D$2:$D$168,B43,'Daily Plan'!$J$2:$J$168) -> 21.5
A44: Inside inference: KV cache, sampling, scaling laws, MoE | B44: W4 | C44: 46314 | D44: =COUNTIF('Daily Plan'!$D$2:$D$168,B44) -> 13 | E44: =COUNTIFS('Daily Plan'!$D$2:$D$168,B44,'Daily Plan'!$L$2:$L$168,"☑")+COUNTIFS('Daily Plan'!$D$2:$D$168,B44,'Daily Plan'!$L$2:$L$168,TRUE()) -> 0 | F44: =IFERROR(E44/D44,0) -> 0 | G44: =SUMIF('Daily Plan'!$D$2:$D$168,B44,'Daily Plan'!$J$2:$J$168) -> 21.5
A45: Embeddings, contrastive learning and vector search internals | B45: W5 | C45: 46321 | D45: =COUNTIF('Daily Plan'!$D$2:$D$168,B45) -> 12 | E45: =COUNTIFS('Daily Plan'!$D$2:$D$168,B45,'Daily Plan'!$L$2:$L$168,"☑")+COUNTIFS('Daily Plan'!$D$2:$D$168,B45,'Daily Plan'!$L$2:$L$168,TRUE()) -> 0 | F45: =IFERROR(E45/D45,0) -> 0 | G45: =SUMIF('Daily Plan'!$D$2:$D$168,B45,'Daily Plan'!$J$2:$J$168) -> 21.5
...

Sheet Daily Plan
A1: # | B1: Date | C1: Day | D1: Week | E1: Phase | F1: Type | G1: Topic | H1: Description | I1: Link | J1: Hours | K1: Deliverable / assignment | L1: Done | M1: Notes
A2: 1 | B2: 46293 | C2: Mon | D2: W1 | E2: P0 | F2: Setup | G2: Workspace + GPU plan | H2: Create one monorepo for all 2026 projects (uv, pytest, ruff, wandb or tensorboard). Decide compute: Mac/Colab for small runs, rented A10/L4/4090 by the hour for training weeks. | I2: https://pytorch.org/get-started/locally/ | J2: 0.5 | K2: Repo skeleton | L2: ☐
A3: 2 | B3: 46293 | C3: Mon | D3: W1 | E3: P0 | F3: Review | G3: Diagnostic self-test | H3: Take the Phase 0 self-test in the checkpoints file. Anything you answer confidently in <2 min is skipped this week. | I3: https://github.com/anshu8830/anshu/blob/main/curriculum/08-skill-checkpoints.md | J3: 1 | K3: List of gaps | L3: ☐
A4: 3 | B4: 46293 | C4: Mon | D4: W1 | E4: P0 | F4: Reading | G4: Probability -> MLE -> cross-entropy; optimizers | H4: UDL ch. 5 (loss functions as MLE) and ch. 6 (SGD, momentum, Adam). Then implement AdamW from scratch and match PyTorch. | I4: https://udlbook.github.io/udlbook/ | J4: 2 | K4: adamw.py + test | L4: ☐
A5: 4 | B5: 46294 | C5: Tue | D5: W1 | E5: P0 | F5: Video | G5: Backprop by hand | H5: Backprop Ninja (skip if diagnostic passed). Exercise: manual backward for Linear->LayerNorm->GELU->Linear->softmax-CE; verify with torch.autograd.gradcheck. | I5: https://www.youtube.com/watch?v=q8SA3rM6ckI | J5: 2 | K5: manual_backward.py | L5: ☐
A6: 5 | B6: 46294 | C6: Tue | D6: W1 | E6: P0 | F6: Reading | G6: Matrix calculus refresh | H6: Parr & Howard sections on vector chain rule + UDL ch. 7. Derive dL/dlogits = softmax - onehot and the LayerNorm backward on paper. | I6: https://explained.ai/matrix-calculus/ | J6: 1.5 | K6: 1-page derivation | L6: ☐
A7: 6 | B7: 46295 | C7: Wed | D7: W1 | E7: P0 | F7: Video | G7: PyTorch + resource accounting | H7: CS336 L2 (trace + video in 2026 playlist): tensors, einops, FLOPs and memory accounting. Exercise: FLOPs of a (B,T,d)x(d,4d) matmul; memory of a 1B model in fp32/bf16 incl. Adam states. | I7: https://cs336.stanford.edu/lectures/?trace=lecture_02 | J7: 1.5 | K7: accounting.md | L7: ☐
A8: 7 | B8: 46295 | C8: Wed | D8: W1 | E8: P0 | F8: Reading | G8: Generalization revision | H8: UDL ch. 8-9: bias/variance, double descent, weight decay, dropout, early stopping. 1 hour max. | I8: https://udlbook.github.io/udlbook/ | J8: 1 | L8: ☐
A9: 8 | B9: 46295 | C9: Wed | D9: W1 | E9: P0 | F9: Code | G9: Evaluation revision | H9: Implement precision/recall/F1, ROC-AUC vs PR-AUC and expected calibration error (ECE) on a toy classifier. | I9: https://udlbook.github.io/udlbook/ | J9: 1 | K9: metrics.py | L9: ☐
A10: 9 | B10: 46296 | C10: Thu | D10: W1 | E10: P1 | F10: Video | G10: Attention intuition | H10: 3Blue1Brown DL5 + DL6 back to back. | I10: https://www.youtube.com/watch?v=eMlx5fFNoYc | J10: 1 | L10: ☐
A11: 10 | B11: 46296 | C11: Thu | D11: W1 | E11: P1 | F11: Reading | G11: Illustrated Transformer | H11: Read end-to-end; sketch the encoder/decoder data flow yourself. | I11: https://jalammar.github.io/illustrated-transformer/ | J11: 1 | K11: Hand-drawn diagram | L11: ☐
A12: 11 | B12: 46296 | C12: Thu | D12: W1 | E12: P13 | F12: Paper | G12: Attention Is All You Need (3-pass) | H12: Read Keshav (15 min), then the paper: 3.1-3.2.3, 3.5, Table 3. Write notes with tensor shapes. | I12: https://arxiv.org/abs/1706.03762 | J12: 1.5 | K12: Paper notes #1 | L12: ☐
A13: 12 | B13: 46297 | C13: Fri | D13: W1 | E13: P1 | F13: Reading | G13: Math -> tensor shapes | H13: Work through the attention concept note; fill every shape in the table yourself before reading the answer. | I13: https://github.com/anshu8830/anshu/blob/main/curriculum/concepts/01-attention-and-transformer.md | J13: 1 | L13: ☐
A14: 13 | B14: 46297 | C14: Fri | D14: W1 | E14: P1 | F14: Code | G14: Scaled dot-product attention | H14: Implement SDPA with causal + padding masks. Tests: equals F.scaled_dot_product_attention (atol 1e-6); perturbing future tokens does not change past outputs. | I14: https://github.com/anshu8830/anshu/blob/main/curriculum/concepts/01-attention-and-transformer.md | J14: 2.5 | K14: P1: sdpa + tests | L14: ☐
A15: 14 | B15: 46298 | C15: Sat | D15: W1 | E15: P1 | F15: Code | G15: Multi-head + cross attention | H15: Fused QKV projection, split heads with view/transpose (or einops), output projection; cross-attention variant. Test against nn.MultiheadAttention with copied weights. | I15: https://nlp.seas.harvard.edu/annotated-transformer/ | J15: 2.5 | K15: P1: mha.py | L15: ☐
A16: 15 | B16: 46298 | C16: Sat | D16: W1 | E16: P1 | F16: Experiment | G16: Attention experiments | H16: (a) remove 1/sqrt(d_k): plot softmax entropy vs d_k; (b) visualize attention maps on a toy sequence; (c) measure attention-matrix memory vs T. | I16: https://github.com/anshu8830/anshu/blob/main/curriculum/concepts/01-attention-and-transformer.md | J16: 1.5 | K16: P1 notebook (DONE) | L16: ☐
A17: 16 | B17: 46300 | C17: Mon | D17: W2 | E17: P1 | F17: Video | G17: Let's build GPT (code along) | H17: Watch at 1.25x and type the code; stop at each stage and predict the next change before Karpathy makes it. | I17: https://www.youtube.com/watch?v=kCc8FmEb1nY | J17: 2.5 | K17: gpt_karpathy.py | L17: ☐
A18: 17 | B18: 46300 | C18: Mon | D18: W2 | E18: P1 | F18: Reading | G18: Annotated Transformer skim | H18: Skim the encoder-decoder parts you will need on Saturday. | I18: https://nlp.seas.harvard.edu/annotated-transformer/ | J18: 1 | L18: ☐
A19: 18 | B19: 46301 | C19: Tue | D19: W2 | E19: P1 | F19: Video | G19: CS336 L3 - Architectures | H19: Video + slides: pre vs post norm, RMSNorm, SwiGLU, RoPE, parallel layers, d_ff = 8/3 d, head dim conventions. | I19: https://www.youtube.com/watch?v=lVynu4bo1rY | J19: 1.5 | K19: Notes | L19: ☐
A20: 19 | B20: 46301 | C20: Tue | D20: W2 | E20: P1 | F20: Reading | G20: Big LLM Architecture Comparison | H20: Read the Llama, Qwen, DeepSeek (MLA/MoE) and gpt-oss sections. | I20: https://magazine.sebastianraschka.com/p/the-big-llm-architecture-comparison | J20: 1 | L20: ☐
A21: 20 | B21: 46301 | C21: Tue | D21: W2 | E21: P13 | F21: Paper | G21: Pre-LN, RMSNorm, GLU variants | H21: Short reads: Pre-LN sec. 1+3 (skip proofs), RMSNorm sec. 3, GLU Variants (whole). | I21: https://arxiv.org/abs/2002.04745 | J21: 1 | K21: Paper notes #2 | L21: ☐
A22: 21 | B22: 46302 | C22: Wed | D22: W2 | E22: P1 | F22: Code | G22: Block components | H22: Embeddings + (learned/sinusoidal) PE, LayerNorm & RMSNorm, FFN vs SwiGLU, pre-norm residual block, weight tying. Parameter-count function tested against ~12*L*d^2 + embeddings. | I22: https://github.com/anshu8830/anshu/blob/main/curriculum/concepts/01-attention-and-transformer.md | J22: 3.5 | K22: P2: components + tests | L22: ☐
A23: 22 | B23: 46303 | C23: Thu | D23: W2 | E23: P1 | F23: Video | G23: RoPE / GQA explained | H23: Umar Jamil LLaMA explained - RoPE, RMSNorm, GQA, SwiGLU sections. | I23: https://www.youtube.com/watch?v=Mn_9W1nCFLo | J23: 1 | L23: ☐
A24: 23 | B24: 46303 | C24: Thu | D24: W2 | E24: P13 | F24: Paper | G24: RoFormer | H24: Sections 3.1-3.4. | I24: https://arxiv.org/abs/2104.09864 | J24: 0.5 | L24: ☐
A25: 24 | B25: 46303 | C25: Thu | D25: W2 | E25: P1 | F25: Code | G25: Implement RoPE | H25: Rotation form; test that <RoPE(q,m), RoPE(k,n)> depends only on m-n; compare interleaved (GPT-J) vs half-split (GPT-NeoX/Llama HF) layouts. | I25: https://github.com/anshu8830/anshu/blob/main/curriculum/concepts/01-attention-and-transformer.md | J25: 2 | K25: P2: rope.py + test | L25: ☐
A26: 25 | B26: 46304 | C26: Fri | D26: W2 | E26: P13 | F26: Paper | G26: MQA + GQA | H26: MQA sec. 2-3, GQA sec. 2-3. Compute KV-cache bytes for a Llama-3-8B-like config under MHA/GQA/MQA. | I26: https://arxiv.org/abs/2305.13245 | J26: 1 | K26: KV math table | L26: ☐
A27: 26 | B27: 46304 | C27: Fri | D27: W2 | E27: P1 | F27: Code | G27: GQA + assemble GPT | H27: GQA via repeat_interleave; flags for MHA/MQA. Assemble decoder-only GPT (dataclass config). Tests: causal leakage, shapes, param count. | I27: https://github.com/anshu8830/anshu/blob/main/curriculum/concepts/01-attention-and-transformer.md | J27: 2.5 | K27: P2: model.py | L27: ☐
A28: 27 | B28: 46305 | C28: Sat | D28: W2 | E28: P1 | F28: Project | G28: Encoder-decoder Transformer | H28: Bidirectional encoder + decoder with cross-attention; train on sequence reversal or 3-digit addition until >99% exact match. | I28: https://nlp.seas.harvard.edu/annotated-transformer/ | J28: 3 | K28: P2: seq2seq.py | L28: ☐
A29: 28 | B29: 46305 | C29: Sat | D29: W2 | E29: P1 | F29: Review | G29: Encoder vs decoder write-up | H29: BERT sec. 3 skim (15 min). Write 1 page: encoder-only vs decoder-only vs enc-dec, and why decoder-only dominates LLMs. | I29: https://arxiv.org/abs/1810.04805 | J29: 1 | K29: P2 README (DONE) | L29: ☐
A30: 29 | B30: 46307 | C30: Mon | D30: W3 | E30: P2 | F30: Video | G30: Let's build the GPT Tokenizer | H30: Watch with minbpe open; pause to implement get_stats/merge yourself. | I30: https://www.youtube.com/watch?v=zduSFxRajkE | J30: 2.5 | L30: ☐
A31: 30 | B31: 46307 | C31: Mon | D31: W3 | E31: P13 | F31: Paper | G31: BPE (Sennrich) + GPT-2 input representation | H31: BPE sec. 3.2 + Algorithm 1; GPT-2 sec. 2.2. | I31: https://arxiv.org/abs/1508.07909 | J31: 1 | K31: Paper notes #3 | L31: ☐
A32: 31 | B32: 46308 | C32: Tue | D32: W3 | E32: P2 | F32: Video | G32: CS336 L1 - Overview & tokenization | H32: Video + A1 handout BPE section. | I32: https://www.youtube.com/watch?v=JuoVZkPBiKk | J32: 1.5 | L32: ☐
A33: 32 | B33: 46308 | C33: Tue | D33: W3 | E33: P2 | F33: Code | G33: BPE trainer v1 | H33: Naive byte-level BPE trainer with GPT-2 pre-tokenization regex and special tokens. | I33: https://github.com/stanford-cs336/assignment1-basics | J33: 2 | K33: P3: bpe_train.py | L33: ☐
A34: 33 | B34: 46309 | C34: Wed | D34: W3 | E34: P2 | F34: Code | G34: BPE trainer v2 + tokenizer | H34: Incremental pair-count updates, parallel pre-tokenization on chunk boundaries; 10K vocab on TinyStories; encode/decode; run A1 tokenizer tests. | I34: https://github.com/stanford-cs336/assignment1-basics | J34: 2 | K34: P3: tokenizer passes A1 tests | L34: ☐
A35: 34 | B35: 46309 | C35: Wed | D35: W3 | E35: P2 | F35: Experiment | G35: SentencePiece vs BPE | H35: Read SentencePiece sec. 2-3; train BPE vs unigram on same text; compare bytes/token and vocab-size trade-off (embedding params vs sequence length). | I35: https://arxiv.org/abs/1808.06226 | J35: 1.5 | K35: Comparison table | L35: ☐
A36: 35 | B36: 46310 | C36: Thu | D36: W3 | E36: P2 | F36: Reading | G36: LM objective math | H36: Concept note: next-token prediction, cross-entropy = NLL, teacher forcing, perplexity, bits-per-byte. | I36: https://github.com/anshu8830/anshu/blob/main/curriculum/concepts/02-prompt-to-next-token.md | J36: 1 | L36: ☐
A37: 36 | B37: 46310 | C37: Thu | D37: W3 | E37: P2 | F37: Code | G37: Training loop (A1 components) | H37: memmap token dataset, random batch sampler, own AdamW, warmup + cosine LR, grad clipping, checkpoint save/load; pass the A1 tests for each. | I37: https://github.com/stanford-cs336/assignment1-basics | J37: 2.5 | K37: P3: train.py | L37: ☐
A38: 37 | B38: 46311 | C38: Fri | D38: W3 | E38: P2 | F38: Experiment | G38: Train on TinyStories | H38: ~20-30M params on one rented GPU (or smaller on MPS). Log train/val loss, tokens/s, estimated MFU. Aim for the A1 handout's TinyStories target. | I38: https://github.com/stanford-cs336/assignment1-basics | J38: 3.5 | K38: Loss curves | L38: ☐
A39: 38 | B39: 46312 | C39: Sat | D39: W3 | E39: P2 | F39: Code | G39: Generation + sampling | H39: Temperature, top-k, top-p sampling; generate 20 stories; read them critically. | I39: https://arxiv.org/abs/1904.09751 | J39: 2 | K39: generate.py | L39: ☐
A40: 39 | B40: 46312 | C40: Sat | D40: W3 | E40: P13 | F40: Experiment | G40: Reproduction #1 - architecture ablations | H40: RoPE vs NoPE vs learned absolute; pre-norm vs post-norm at high LR (Pre-LN paper claim); 3-point LR sweep. Plot and explain. | I40: https://arxiv.org/abs/2002.04745 | J40: 2 | K40: Ablation report | L40: ☐
...

Sheet Projects
A1: ID | B1: Project | C1: Weeks | D1: Due | E1: Deliverable | F1: Skills developed | G1: Status | H1: Done | I1: Your repo link / notes
A2: P1 | B2: Attention from scratch | C2: W1 | D2: 46298 | E2: attention.py (SDPA, masks, MHA, cross-attn) + pytest suite + experiment notebook | F2: Q/K/V shapes, masking, sqrt(d_k) scaling, tests against PyTorch reference | G2: Not started | H2: ☐
A3: P2 | B3: Transformer from scratch | C3: W2 | D3: 46305 | E3: Decoder-only GPT (RoPE, RMSNorm, SwiGLU, GQA) + encoder-decoder trained on a toy seq2seq task | F3: Block design, pre-norm residuals, RoPE, GQA, param counting | G3: Not started | H3: ☐
A4: P3 | B4: Tokenizer + small GPT trained end-to-end | C4: W3-W4 | D4: 46319 | E4: Byte-level BPE, training loop, TinyStories model, KV-cache generation, sampling suite, ablation report | F4: BPE, cross-entropy/perplexity, AdamW + schedules, KV cache, sampling, scaling-law fit, MoE layer | G4: Not started | H4: ☐
A5: P4 | B5: Embedding & retrieval engine | C5: W5 | D5: 46326 | E5: BM25, IVF-PQ, HNSW (own + FAISS), hybrid RRF, reranker, pgvector/Qdrant backend, benchmark report | F5: Contrastive learning, sparse vs dense retrieval, ANN algorithms, IR metrics | G5: Not started | H5: ☐
A6: P5 | B6: Advanced RAG system | C6: W6 | D6: 46333 | E6: Config-driven RAG: parsing, chunking variants, query rewriting/HyDE, hybrid+rerank, agentic router, citations | F6: Every RAG stage + its failure modes, ablation discipline | G6: Not started | H6: ☐
A7: P6 | B7: RAG / LLM evaluation framework | C7: W7 | D7: 46340 | E7: ragevals: golden sets, retrieval + judge metrics, judge calibration, bootstrap CIs, CI regression gate | F7: Error analysis, LLM-as-judge, faithfulness, statistics, regression testing | G7: Not started | H7: ☐
A8: P7 | B8: Fine-tune an open LLM (SFT + LoRA/QLoRA + DPO + GRPO) | C8: W8-W9 | D8: 46354 | E8: SFT-from-scratch, LoRA-from-scratch, QLoRA 8B run, DPO run, GRPO run on verifiable math, eval report | F8: Chat templates, loss masking, LoRA/QLoRA, preference optimization, RLVR | G8: Not started | H8: ☐
A9: P8 | B9: AI research agent | C9: W10 | D9: 46361 | E9: Framework-free agent loop -> planning, memory, reflection, HITL; LangGraph port; agent eval on 20 tasks | F9: Tool calling, ReAct, memory, multi-agent, agent security, agent evaluation | G9: Not started | H9: ☐
A10: P9 | B10: Custom MCP server | C10: W10 | D10: 46361 | E10: MCP server over your retrieval engine: tools + resources + prompts, stdio + Streamable HTTP, auth, tests | F10: MCP architecture, transports, auth, tool design | G10: Not started | H10: ☐
A11: P10 | B11: Optimize & serve an LLM with vLLM | C11: W11 | D11: 46368 | E11: Benchmarked vLLM deployment: BF16/FP8/INT4, prefix caching, spec decoding; perf report with roofline math | F11: GPU fundamentals, KV cache, batching, quantization, TTFT/TPOT | G11: Not started | H11: ☐
A12: P11 | B12: Multimodal RAG | C12: W12 | D12: 46375 | E12: PDF/figure/table/audio RAG: Docling + ColPali-style page retrieval + VLM answers with page citations | F12: ViT/CLIP, VLM architecture, document understanding, Whisper | G12: Not started | H12: ☐
A13: CAP | B13: Capstone: AI Software Engineer | C13: W13-W14 | D13: 46387 | E13: Repo-aware coding agent with RAG, MCP, memory, planning, sandboxed execution, routing, HITL, eval on SWE-bench subset | F13: Everything - integration, evaluation and hardening | G13: Not started | H13: ☐

Sheet Papers
A1: # | B1: Title | C1: Authors | D1: Year | E1: Difficulty (1-5) | F1: Week | G1: Link | H1: Why it matters | I1: Prerequisites | J1: Read carefully | K1: Implement | L1: Reproduce | M1: Tier | N1: Read | O1: Notes
A2: 1 | B2: How to Read a Paper | C2: S. Keshav | D2: 2007 | E2: 1 | F2: W1 | G2: http://ccr.sigcomm.org/online/files/p83-keshavA.pdf | H2: The three-pass method you will use for every paper below. | I2: None. | J2: Whole paper (2 pages). | K2: A paper-notes template in your repo. | L2: - | M2: CORE | N2: ☐
A3: 2 | B3: Improving Language Understanding by Generative Pre-Training (GPT-1) | C3: Radford, Narasimhan, Salimans, Sutskever | D3: 2018 | E3: 1 | F3: W2 | G3: https://cdn.openai.com/research-covers/language-unsupervised/language_understanding_paper.pdf | H3: Origin of generative pretraining + fine-tuning. | I3: Attention Is All You Need. | J3: Sections 1, 3.1-3.3. | K3: - | L3: - | M3: CORE | N3: ☐
A4: 3 | B4: GLU Variants Improve Transformer | C4: Shazeer | D4: 2020 | E4: 1 | F4: W2 | G4: https://arxiv.org/abs/2002.05202 | H4: Source of SwiGLU used in Llama/Qwen. | I4: FFN block; gating. | J4: Whole paper (4 pages). | K4: SwiGLU FFN. | L4: - | M4: CORE | N4: ☐
A5: 4 | B5: Neural Machine Translation of Rare Words with Subword Units (BPE) | C5: Sennrich, Haddow, Birch | D5: 2015 | E5: 1 | F5: W3 | G5: https://arxiv.org/abs/1508.07909 | H5: The BPE algorithm behind GPT tokenizers. | I5: None. | J5: Section 3.2 + Algorithm 1. | K5: BPE trainer (P3). | L5: - | M5: CORE | N5: ☐
A6: 5 | B6: SentencePiece | C6: Kudo, Richardson | D6: 2018 | E6: 1 | F6: W3 | G6: https://arxiv.org/abs/1808.06226 | H6: Language-independent tokenization; unigram LM alternative. | I6: BPE paper. | J6: Sections 2-3. | K6: Train BPE vs unigram and compare. | L6: - | M6: CORE | N6: ☐
A7: 6 | B7: Lost in the Middle | C7: Liu, Lin, Hewitt, Paranjape, Bevilacqua, Petroni, Liang | D7: 2023 | E7: 1 | F7: W6 | G7: https://arxiv.org/abs/2307.03172 | H7: Position effects in long contexts - drives context ordering. | I7: RAG basics. | J7: Sections 2-4. | K7: - | L7: Position sweep on your RAG. | M7: CORE | N7: ☐
A8: 7 | B8: Chain-of-Thought Prompting | C8: Wei et al. | D8: 2022 | E8: 1 | F8: W9 | G8: https://arxiv.org/abs/2201.11903 | H8: Reasoning traces as a capability lever. | I8: Prompting. | J8: Sections 2-3. | K8: - | L8: - | M8: CORE | N8: ☐
A9: 8 | B9: Attention Is All You Need | C9: Vaswani, Shazeer, Parmar, Uszkoreit, Jones, Gomez, Kaiser, Polosukhin | D9: 2017 | E9: 2 | F9: W1 | G9: https://arxiv.org/abs/1706.03762 | H9: Defines the architecture everything else modifies. | I9: Matrix multiplication, softmax, residual nets; the W1 attention concept note. | J9: 3.1-3.2.3 (attention + multi-head), 3.5 (positional encoding), Table 3 ablations. | K9: Scaled dot-product attention, MHA, sinusoidal PE (P1/P2). | L9: Table 3 row (A): vary heads at fixed compute on a toy task. | M9: CORE | N9: ☐
A10: 9 | B10: BERT: Pre-training of Deep Bidirectional Transformers | C10: Devlin, Chang, Lee, Toutanova | D10: 2018 | E10: 2 | F10: W2 | G10: https://arxiv.org/abs/1810.04805 | H10: Encoder-only counterpart; explains why bidirectional encoders still dominate embeddings/rerankers. | I10: Transformer encoder; masked vs causal attention. | J10: Sections 3.1-3.2 (MLM, NSP), Figure 1. | K10: Masked-LM objective on your encoder (optional). | L10: - | M10: CORE | N10: ☐
A11: 10 | B11: Language Models are Unsupervised Multitask Learners (GPT-2) | C11: Radford, Wu, Child, Luan, Amodei, Sutskever | D11: 2019 | E11: 2 | F11: W2 | G11: https://cdn.openai.com/better-language-models/language_models_are_unsupervised_multitask_learners.pdf | H11: Zero-shot task transfer from pure LM; byte-level BPE; pre-norm. | I11: GPT-1; byte-level BPE idea. | J11: Sections 2.1-2.3 (data, input representation, model changes). | K11: Byte-level BPE (P3). | L11: - | M11: CORE | N11: ☐
A12: 11 | B12: Root Mean Square Layer Normalization | C12: Zhang, Sennrich | D12: 2019 | E12: 2 | F12: W2 | G12: https://arxiv.org/abs/1910.07467 | H12: Why modern LLMs dropped mean-centering. | I12: LayerNorm forward/backward. | J12: Sections 2-3. | K12: RMSNorm layer + test. | L12: - | M12: CORE | N12: ☐
A13: 12 | B13: Fast Transformer Decoding: One Write-Head is All You Need (MQA) | C13: Shazeer | D13: 2019 | E13: 2 | F13: W2 | G13: https://arxiv.org/abs/1911.02150 | H13: First paper to attack KV-cache bandwidth. | I13: MHA; KV cache (W4 concept note helps). | J13: Sections 2-3. | K13: MQA as GQA special case. | L13: - | M13: CORE | N13: ☐
... A82: 81 | B82: DeepSeek-V3 Technical Report | C82: DeepSeek-AI | D82: 2024 | E82: 4 | F82: 2027 | G82: https://arxiv.org/abs/2412.19437 | H82: MLA, auxiliary-loss-free MoE balancing, FP8 training, MTP - a frontier training systems case study. | I82: MoE, MLA, FP8, pipeline parallelism. | J82: Sections 2-3. | K82: - | L82: - | M82: EXT | N82: ☐

Sheet Resources
A1: Kind | B1: Title | C1: By / channel | D1: Duration | E1: Link | F1: Week(s) | G1: Why / notes
A2: PRIMARY | B2: Understanding Deep Learning (Prince), ch. 5-9 - targeted revision | E2: https://udlbook.github.io/udlbook/ | F2: W1
A3: PRIMARY | B3: CS336 2026 Lecture 2 trace - PyTorch, einops, resource accounting | E3: https://cs336.stanford.edu/lectures/?trace=lecture_02 | F3: W1
A4: PRIMARY | B4: Concept note: attention & transformer shapes | E4: https://github.com/anshu8830/anshu/blob/main/curriculum/concepts/01-attention-and-transformer.md | F4: W1, W2
A5: PRIMARY | B5: The Illustrated Transformer (Alammar) | E5: https://jalammar.github.io/illustrated-transformer/ | F5: W1
A6: SECONDARY | B6: The Matrix Calculus You Need for Deep Learning | E6: https://explained.ai/matrix-calculus/ | F6: W1
A7: SECONDARY | B7: The Annotated Transformer | E7: https://nlp.seas.harvard.edu/annotated-transformer/ | F7: W1, W2
A8: REFERENCE | B8: How to Read a Paper (Keshav) | E8: http://ccr.sigcomm.org/online/files/p83-keshavA.pdf | F8: W1
A9: VIDEO | B9: Building makemore Part 4: Becoming a Backprop Ninja | C9: Andrej Karpathy | D9: 1h55m | E9: https://www.youtube.com/watch?v=q8SA3rM6ckI | F9: W1 | G9: Only if the diagnostic shows you can't write a manual backward pass; the best drill for gradient flow. (P0 backprop)
A10: VIDEO | B10: Transformers, the tech behind LLMs | DL5 | C10: 3Blue1Brown | D10: 27m | E10: https://www.youtube.com/watch?v=wjZofJX0v4M | F10: W1 | G10: Geometric intuition for embeddings and next-token prediction before any equations. (P1 intuition)
A11: VIDEO | B11: Attention in transformers, step-by-step | DL6 | C11: 3Blue1Brown | D11: 26m | E11: https://www.youtube.com/watch?v=eMlx5fFNoYc | F11: W1 | G11: Clearest visual explanation of Q, K, V and why masking exists. (P1 attention)
A12: VIDEO | B12: Let's build GPT (Karpathy) - code along | C12: Andrej Karpathy | D12: 1h56m | E12: https://www.youtube.com/watch?v=kCc8FmEb1nY | F12: W2 | G12: Fastest route from bigram model to a working decoder block; you will diverge from it with modern components. (P1 implementation)
A13: PRIMARY | B13: CS336 2026 Lecture 3 - Architectures & hyperparameters (slides) | E13: https://github.com/stanford-cs336/lectures/blob/main/lecture_03.pdf | F13: W2
A14: SECONDARY | B14: The Big LLM Architecture Comparison (Raschka, updated 2026) | E14: https://magazine.sebastianraschka.com/p/the-big-llm-architecture-comparison | F14: W2
A15: REFERENCE | B15: Build a Large Language Model (From Scratch) code | E15: https://github.com/rasbt/LLMs-from-scratch | F15: W2
A16: VIDEO | B16: Stanford CS336 Spring 2026 - Lecture 3: Architectures | C16: Tatsu Hashimoto (Stanford) | D16: ~1h20m | E16: https://www.youtube.com/watch?v=lVynu4bo1rY | F16: W2 | G16: Evidence-based survey of pre-norm, RMSNorm, SwiGLU, RoPE, GQA and hyperparameter conventions across real LLMs. (P1 architecture)
A17: VIDEO | B17: LLaMA explained: KV-Cache, RoPE, RMS Norm, GQA, SwiGLU | C17: Umar Jamil | D17: ~1h10m | E17: https://www.youtube.com/watch?v=Mn_9W1nCFLo | F17: W2 | G17: Best derivation-level explanation of RoPE and GQA with code. (P1 RoPE/GQA)
A18: PRIMARY | B18: CS336 Assignment 1 (Basics) - handout + tests are the spec | E18: https://github.com/stanford-cs336/assignment1-basics | F18: W3
A19: VIDEO | B19: Let's build the GPT Tokenizer (Karpathy) + minbpe | C19: Andrej Karpathy | D19: 2h13m | E19: https://www.youtube.com/watch?v=zduSFxRajkE | F19: W3 | G19: Explains byte-level BPE, regex pre-tokenization, special tokens and the weird failures tokenization causes. (P2 tokenization)
A20: PRIMARY | B20: Concept note: prompt -> next token (loss, perplexity sections) | E20: https://github.com/anshu8830/anshu/blob/main/curriculum/concepts/02-prompt-to-next-token.md | F20: W3, W4
A21: SECONDARY | B21: minbpe reference implementation | E21: https://github.com/karpathy/minbpe | F21: W3
A22: SECONDARY | B22: nanoGPT reference | E22: https://github.com/karpathy/nanoGPT | F22: W3
A23: REFERENCE | B23: A Recipe for Training Neural Networks (Karpathy) | E23: http://karpathy.github.io/2019/04/25/recipe/ | F23: W3
A24: VIDEO | B24: Stanford CS336 Spring 2026 - Lecture 1: Overview, Tokenization | C24: Percy Liang (Stanford) | D24: ~1h20m | E24: https://www.youtube.com/watch?v=JuoVZkPBiKk | F24: W3 | G24: Frames the whole LM pipeline and the tokenizer design space used in A1. (P2 tokenization)
A25: PRIMARY | B25: CS336 2026 Lecture 10 trace - Inference | E25: https://cs336.stanford.edu/lectures/?trace=lecture_10 | F25: W4
A26: PRIMARY | B26: CS336 2026 Lecture 9 slides - Scaling laws | E26: https://github.com/stanford-cs336/lectures/blob/main/lecture_09.pdf | F26: W4
A27: PRIMARY | B27: CS336 2026 Lecture 4 slides - Attention alternatives & MoE | E27: https://github.com/stanford-cs336/lectures/blob/main/lecture_04.pdf | F27: W4
A28: SECONDARY | B28: Transformer Inference Arithmetic (kipply) | E28: https://kipply.github.io/blog/transformer-inference-arithmetic/ | F28: W4
A29: SECONDARY | B29: A Visual Guide to Mixture of Experts (Grootendorst) | E29: https://newsletter.maartengrootendorst.com/p/a-visual-guide-to-mixture-of-experts | F29: W4
A30: SECONDARY | B30: LLM Visualization (Bycroft) - 3D walk through one token | E30: https://bbycroft.net/llm | F30: W4
A31: VIDEO | B31: CS336 2026 playlist (lectures 4, 9, 10, 11) | C31: Liang / Hashimoto (Stanford) | D31: ~1h20m each | E31: https://www.youtube.com/playlist?list=PLoROMvodv4rMqXOcazWaTUHhq-yembLCV | F31: W4, W7, W8, W9, W12 | G31: Collective communication and DP/TP/PP trade-offs with real numbers. (P11 distributed)
A32: VIDEO | B32: Stanford CS229: Building Large Language Models (LLMs) | C32: Yann Dubois (Stanford) | D32: ~1h44m | E32: https://www.youtube.com/watch?v=9vM4p9NN0Ts | F32: W4 | G32: Optional single-sitting overview tying pretraining, scaling laws, evaluation and post-training together. (P2 overview)
A33: PRIMARY | B33: Concept note: retrieval & vector search | E33: https://github.com/anshu8830/anshu/blob/main/curriculum/concepts/03-retrieval-and-vector-search.md | F33: W5
A34: PRIMARY | B34: Introduction to Information Retrieval - ch. 6 & 11.4.3 (BM25) | E34: https://nlp.stanford.edu/IR-book/html/htmledition/irbook.html | F34: W5
A35: PRIMARY | B35: Faiss: The Missing Manual (Pinecone) - indexes, PQ, HNSW chapters | E35: https://www.pinecone.io/learn/series/faiss/ | F35: W5
A36: SECONDARY | B36: bm25s (fast reference BM25) | E36: https://github.com/xhluca/bm25s | F36: W5
A37: SECONDARY | B37: The Faiss library paper | E37: https://arxiv.org/abs/2401.08281 | F37: W5
A38: REFERENCE | B38: pgvector | E38: https://github.com/pgvector/pgvector | F38: W5
A39: REFERENCE | B39: Qdrant docs | E39: https://qdrant.tech/documentation/ | F39: W5
A40: REFERENCE | B40: Sentence-Transformers docs | E40: https://sbert.net/ | F40: W5
...
